2021-03-28 12:15:58,771 -  * Running on http://127.0.0.2:5000/ (Press CTRL+C to quit)
2021-03-28 12:16:02,784 - Exception on / [GET]
Traceback (most recent call last):
  File "//anaconda3/lib/python3.7/site-packages/flask/app.py", line 2446, in wsgi_app
    response = self.full_dispatch_request()
  File "//anaconda3/lib/python3.7/site-packages/flask/app.py", line 1951, in full_dispatch_request
    rv = self.handle_user_exception(e)
  File "//anaconda3/lib/python3.7/site-packages/flask_restful/__init__.py", line 272, in error_router
    return original_handler(e)
  File "//anaconda3/lib/python3.7/site-packages/flask/app.py", line 1820, in handle_user_exception
    reraise(exc_type, exc_value, tb)
  File "//anaconda3/lib/python3.7/site-packages/flask/_compat.py", line 39, in reraise
    raise value
  File "//anaconda3/lib/python3.7/site-packages/flask/app.py", line 1949, in full_dispatch_request
    rv = self.dispatch_request()
  File "//anaconda3/lib/python3.7/site-packages/flask/app.py", line 1935, in dispatch_request
    return self.view_functions[rule.endpoint](**req.view_args)
  File "catalog_microservice.py", line 99, in default_query
    json_data = json.loads(request.data.decode(encoding='UTF-8'))
  File "//anaconda3/lib/python3.7/json/__init__.py", line 348, in loads
    return _default_decoder.decode(s)
  File "//anaconda3/lib/python3.7/json/decoder.py", line 337, in decode
    obj, end = self.raw_decode(s, idx=_w(s, 0).end())
  File "//anaconda3/lib/python3.7/json/decoder.py", line 355, in raw_decode
    raise JSONDecodeError("Expecting value", s, err.value) from None
json.decoder.JSONDecodeError: Expecting value: line 1 column 1 (char 0)
2021-03-28 12:16:02,786 - 127.0.0.2 - - [28/Mar/2021 12:16:02] "[35m[1mGET / HTTP/1.1[0m" 500 -
